[2024-10-10T17:46:41.904+0000] {taskinstance.py:1159} INFO - Dependencies all met for dep_context=non-requeueable deps ti=<TaskInstance: green_data_ingestion_gcs_dag.download_dataset_task manual__2024-10-10T17:36:22.618681+00:00 [queued]>
[2024-10-10T17:46:41.907+0000] {taskinstance.py:1159} INFO - Dependencies all met for dep_context=requeueable deps ti=<TaskInstance: green_data_ingestion_gcs_dag.download_dataset_task manual__2024-10-10T17:36:22.618681+00:00 [queued]>
[2024-10-10T17:46:41.907+0000] {taskinstance.py:1361} INFO - Starting attempt 2 of 2
[2024-10-10T17:46:41.912+0000] {taskinstance.py:1382} INFO - Executing <Task(PythonOperator): download_dataset_task> on 2024-10-10 17:36:22.618681+00:00
[2024-10-10T17:46:41.915+0000] {standard_task_runner.py:57} INFO - Started process 29956 to run task
[2024-10-10T17:46:41.916+0000] {standard_task_runner.py:84} INFO - Running: ['***', 'tasks', 'run', 'green_data_ingestion_gcs_dag', 'download_dataset_task', 'manual__2024-10-10T17:36:22.618681+00:00', '--job-id', '36', '--raw', '--subdir', 'DAGS_FOLDER/green_data_ingestion_gcs_dag.py', '--cfg-path', '/tmp/tmp0gcuem7m']
[2024-10-10T17:46:41.917+0000] {standard_task_runner.py:85} INFO - Job 36: Subtask download_dataset_task
[2024-10-10T17:46:41.937+0000] {task_command.py:416} INFO - Running <TaskInstance: green_data_ingestion_gcs_dag.download_dataset_task manual__2024-10-10T17:36:22.618681+00:00 [running]> on host 72e947e9fa68
[2024-10-10T17:46:41.963+0000] {taskinstance.py:1662} INFO - Exporting env vars: AIRFLOW_CTX_DAG_OWNER='***' AIRFLOW_CTX_DAG_ID='green_data_ingestion_gcs_dag' AIRFLOW_CTX_TASK_ID='download_dataset_task' AIRFLOW_CTX_EXECUTION_DATE='2024-10-10T17:36:22.618681+00:00' AIRFLOW_CTX_TRY_NUMBER='2' AIRFLOW_CTX_DAG_RUN_ID='manual__2024-10-10T17:36:22.618681+00:00'
[2024-10-10T17:46:45.787+0000] {taskinstance.py:1937} ERROR - Task failed with exception
Traceback (most recent call last):
  File "/home/airflow/.local/lib/python3.8/site-packages/airflow/operators/python.py", line 192, in execute
    return_value = self.execute_callable()
  File "/home/airflow/.local/lib/python3.8/site-packages/airflow/operators/python.py", line 209, in execute_callable
    return self.python_callable(*self.op_args, **self.op_kwargs)
  File "/opt/airflow/dags/green_data_ingestion_gcs_dag.py", line 46, in download_data_and_concat
    final_table = pa.Table.from_pands(final_pf)
AttributeError: type object 'pyarrow.lib.Table' has no attribute 'from_pands'
[2024-10-10T17:46:45.793+0000] {taskinstance.py:1400} INFO - Marking task as FAILED. dag_id=green_data_ingestion_gcs_dag, task_id=download_dataset_task, execution_date=20241010T173622, start_date=20241010T174641, end_date=20241010T174645
[2024-10-10T17:46:45.799+0000] {standard_task_runner.py:104} ERROR - Failed to execute job 36 for task download_dataset_task (type object 'pyarrow.lib.Table' has no attribute 'from_pands'; 29956)
[2024-10-10T17:46:45.811+0000] {local_task_job_runner.py:228} INFO - Task exited with return code 1
[2024-10-10T17:46:45.822+0000] {taskinstance.py:2778} INFO - 0 downstream tasks scheduled from follow-on schedule check
