[2024-10-16T00:04:36.256+0000] {taskinstance.py:1159} INFO - Dependencies all met for dep_context=non-requeueable deps ti=<TaskInstance: green_data_ingestion_gcs_dag.download_dataset_task scheduled__2024-10-15T00:00:00+00:00 [queued]>
[2024-10-16T00:04:36.260+0000] {taskinstance.py:1159} INFO - Dependencies all met for dep_context=requeueable deps ti=<TaskInstance: green_data_ingestion_gcs_dag.download_dataset_task scheduled__2024-10-15T00:00:00+00:00 [queued]>
[2024-10-16T00:04:36.260+0000] {taskinstance.py:1361} INFO - Starting attempt 1 of 2
[2024-10-16T00:04:36.265+0000] {taskinstance.py:1382} INFO - Executing <Task(PythonOperator): download_dataset_task> on 2024-10-15 00:00:00+00:00
[2024-10-16T00:04:36.267+0000] {standard_task_runner.py:57} INFO - Started process 1272 to run task
[2024-10-16T00:04:36.269+0000] {standard_task_runner.py:84} INFO - Running: ['***', 'tasks', 'run', 'green_data_ingestion_gcs_dag', 'download_dataset_task', 'scheduled__2024-10-15T00:00:00+00:00', '--job-id', '85', '--raw', '--subdir', 'DAGS_FOLDER/green_data_ingestion_gcs_dag.py', '--cfg-path', '/tmp/tmpm95hk6s2']
[2024-10-16T00:04:36.269+0000] {standard_task_runner.py:85} INFO - Job 85: Subtask download_dataset_task
[2024-10-16T00:04:36.289+0000] {task_command.py:416} INFO - Running <TaskInstance: green_data_ingestion_gcs_dag.download_dataset_task scheduled__2024-10-15T00:00:00+00:00 [running]> on host 63fbd9348e70
[2024-10-16T00:04:36.321+0000] {taskinstance.py:1662} INFO - Exporting env vars: AIRFLOW_CTX_DAG_OWNER='***' AIRFLOW_CTX_DAG_ID='green_data_ingestion_gcs_dag' AIRFLOW_CTX_TASK_ID='download_dataset_task' AIRFLOW_CTX_EXECUTION_DATE='2024-10-15T00:00:00+00:00' AIRFLOW_CTX_TRY_NUMBER='1' AIRFLOW_CTX_DAG_RUN_ID='scheduled__2024-10-15T00:00:00+00:00'
[2024-10-16T00:15:51.270+0000] {local_task_job_runner.py:294} WARNING - State of this instance has been externally set to up_for_retry. Terminating instance.
[2024-10-16T00:15:51.273+0000] {process_utils.py:131} INFO - Sending 15 to group 1272. PIDs of all processes in the group: [1272]
[2024-10-16T00:15:51.273+0000] {process_utils.py:86} INFO - Sending the signal 15 to group 1272
[2024-10-16T00:15:51.274+0000] {taskinstance.py:1632} ERROR - Received SIGTERM. Terminating subprocesses.
[2024-10-16T00:15:51.281+0000] {taskinstance.py:1937} ERROR - Task failed with exception
Traceback (most recent call last):
  File "/home/airflow/.local/lib/python3.8/site-packages/airflow/operators/python.py", line 192, in execute
    return_value = self.execute_callable()
  File "/home/airflow/.local/lib/python3.8/site-packages/airflow/operators/python.py", line 209, in execute_callable
    return self.python_callable(*self.op_args, **self.op_kwargs)
  File "/opt/airflow/dags/green_data_ingestion_gcs_dag.py", line 42, in download_data_and_concat
    pf = pd.read_parquet(url)
  File "/home/airflow/.local/lib/python3.8/site-packages/pandas/io/parquet.py", line 509, in read_parquet
    return impl.read(
  File "/home/airflow/.local/lib/python3.8/site-packages/pandas/io/parquet.py", line 220, in read
    path_or_handle, handles, kwargs["filesystem"] = _get_path_or_handle(
  File "/home/airflow/.local/lib/python3.8/site-packages/pandas/io/parquet.py", line 110, in _get_path_or_handle
    handles = get_handle(
  File "/home/airflow/.local/lib/python3.8/site-packages/pandas/io/common.py", line 716, in get_handle
    ioargs = _get_filepath_or_buffer(
  File "/home/airflow/.local/lib/python3.8/site-packages/pandas/io/common.py", line 373, in _get_filepath_or_buffer
    reader = BytesIO(req.read())
  File "/usr/local/lib/python3.8/http/client.py", line 472, in read
    s = self._safe_read(self.length)
  File "/usr/local/lib/python3.8/http/client.py", line 613, in _safe_read
    data = self.fp.read(amt)
  File "/usr/local/lib/python3.8/socket.py", line 669, in readinto
    return self._sock.recv_into(b)
  File "/usr/local/lib/python3.8/ssl.py", line 1274, in recv_into
    return self.read(nbytes, buffer)
  File "/usr/local/lib/python3.8/ssl.py", line 1132, in read
    return self._sslobj.read(len, buffer)
  File "/home/airflow/.local/lib/python3.8/site-packages/airflow/models/taskinstance.py", line 1634, in signal_handler
    raise AirflowException("Task received SIGTERM signal")
airflow.exceptions.AirflowException: Task received SIGTERM signal
[2024-10-16T00:15:51.284+0000] {taskinstance.py:1400} INFO - Marking task as FAILED. dag_id=green_data_ingestion_gcs_dag, task_id=download_dataset_task, execution_date=20241015T000000, start_date=20241016T000436, end_date=20241016T001551
[2024-10-16T00:15:51.291+0000] {standard_task_runner.py:104} ERROR - Failed to execute job 85 for task download_dataset_task (Task received SIGTERM signal; 1272)
[2024-10-16T00:15:51.311+0000] {process_utils.py:79} INFO - Process psutil.Process(pid=1272, status='terminated', exitcode=1, started='00:04:35') (1272) terminated with exit code 1
