[2024-10-15T21:30:28.689+0000] {taskinstance.py:1159} INFO - Dependencies all met for dep_context=non-requeueable deps ti=<TaskInstance: yellow_data_ingestion_gcs_dag.download_dataset_task manual__2024-10-15T21:24:42.004335+00:00 [queued]>
[2024-10-15T21:30:28.692+0000] {taskinstance.py:1159} INFO - Dependencies all met for dep_context=requeueable deps ti=<TaskInstance: yellow_data_ingestion_gcs_dag.download_dataset_task manual__2024-10-15T21:24:42.004335+00:00 [queued]>
[2024-10-15T21:30:28.692+0000] {taskinstance.py:1361} INFO - Starting attempt 2 of 2
[2024-10-15T21:30:28.697+0000] {taskinstance.py:1382} INFO - Executing <Task(PythonOperator): download_dataset_task> on 2024-10-15 21:24:42.004335+00:00
[2024-10-15T21:30:28.699+0000] {standard_task_runner.py:57} INFO - Started process 71 to run task
[2024-10-15T21:30:28.701+0000] {standard_task_runner.py:84} INFO - Running: ['***', 'tasks', 'run', 'yellow_data_ingestion_gcs_dag', 'download_dataset_task', 'manual__2024-10-15T21:24:42.004335+00:00', '--job-id', '73', '--raw', '--subdir', 'DAGS_FOLDER/yellow_data_ingestion_gcs_dag.py', '--cfg-path', '/tmp/tmpuwdg92qp']
[2024-10-15T21:30:28.702+0000] {standard_task_runner.py:85} INFO - Job 73: Subtask download_dataset_task
[2024-10-15T21:30:28.721+0000] {task_command.py:416} INFO - Running <TaskInstance: yellow_data_ingestion_gcs_dag.download_dataset_task manual__2024-10-15T21:24:42.004335+00:00 [running]> on host 63fbd9348e70
[2024-10-15T21:30:28.750+0000] {taskinstance.py:1662} INFO - Exporting env vars: AIRFLOW_CTX_DAG_OWNER='***' AIRFLOW_CTX_DAG_ID='yellow_data_ingestion_gcs_dag' AIRFLOW_CTX_TASK_ID='download_dataset_task' AIRFLOW_CTX_EXECUTION_DATE='2024-10-15T21:24:42.004335+00:00' AIRFLOW_CTX_TRY_NUMBER='2' AIRFLOW_CTX_DAG_RUN_ID='manual__2024-10-15T21:24:42.004335+00:00'
[2024-10-15T21:30:28.752+0000] {taskinstance.py:1937} ERROR - Task failed with exception
Traceback (most recent call last):
  File "/home/airflow/.local/lib/python3.8/site-packages/airflow/operators/python.py", line 192, in execute
    return_value = self.execute_callable()
  File "/home/airflow/.local/lib/python3.8/site-packages/airflow/operators/python.py", line 209, in execute_callable
    return self.python_callable(*self.op_args, **self.op_kwargs)
  File "/opt/airflow/dags/yellow_data_ingestion_gcs_dag.py", line 43, in download_data_and_concat
    time.sleep(2)
NameError: name 'time' is not defined
[2024-10-15T21:30:28.755+0000] {taskinstance.py:1400} INFO - Marking task as FAILED. dag_id=yellow_data_ingestion_gcs_dag, task_id=download_dataset_task, execution_date=20241015T212442, start_date=20241015T213028, end_date=20241015T213028
[2024-10-15T21:30:28.759+0000] {standard_task_runner.py:104} ERROR - Failed to execute job 73 for task download_dataset_task (name 'time' is not defined; 71)
[2024-10-15T21:30:28.802+0000] {local_task_job_runner.py:228} INFO - Task exited with return code 1
[2024-10-15T21:30:28.812+0000] {taskinstance.py:2778} INFO - 0 downstream tasks scheduled from follow-on schedule check
