[2024-10-04T01:23:22.843+0000] {taskinstance.py:1159} INFO - Dependencies all met for dep_context=non-requeueable deps ti=<TaskInstance: data_ingestion_gcs_dag.local_to_gcs_task scheduled__2024-10-03T00:00:00+00:00 [queued]>
[2024-10-04T01:23:22.847+0000] {taskinstance.py:1159} INFO - Dependencies all met for dep_context=requeueable deps ti=<TaskInstance: data_ingestion_gcs_dag.local_to_gcs_task scheduled__2024-10-03T00:00:00+00:00 [queued]>
[2024-10-04T01:23:22.847+0000] {taskinstance.py:1361} INFO - Starting attempt 2 of 2
[2024-10-04T01:23:22.852+0000] {taskinstance.py:1382} INFO - Executing <Task(PythonOperator): local_to_gcs_task> on 2024-10-03 00:00:00+00:00
[2024-10-04T01:23:22.854+0000] {standard_task_runner.py:57} INFO - Started process 882 to run task
[2024-10-04T01:23:22.856+0000] {standard_task_runner.py:84} INFO - Running: ['***', 'tasks', 'run', 'data_ingestion_gcs_dag', 'local_to_gcs_task', 'scheduled__2024-10-03T00:00:00+00:00', '--job-id', '13', '--raw', '--subdir', 'DAGS_FOLDER/data_ingestion_gcs_dag.py', '--cfg-path', '/tmp/tmplmjs87df']
[2024-10-04T01:23:22.857+0000] {standard_task_runner.py:85} INFO - Job 13: Subtask local_to_gcs_task
[2024-10-04T01:23:22.875+0000] {task_command.py:416} INFO - Running <TaskInstance: data_ingestion_gcs_dag.local_to_gcs_task scheduled__2024-10-03T00:00:00+00:00 [running]> on host 03c42f8e6cda
[2024-10-04T01:23:22.905+0000] {taskinstance.py:1662} INFO - Exporting env vars: AIRFLOW_CTX_DAG_OWNER='***' AIRFLOW_CTX_DAG_ID='data_ingestion_gcs_dag' AIRFLOW_CTX_TASK_ID='local_to_gcs_task' AIRFLOW_CTX_EXECUTION_DATE='2024-10-03T00:00:00+00:00' AIRFLOW_CTX_TRY_NUMBER='2' AIRFLOW_CTX_DAG_RUN_ID='scheduled__2024-10-03T00:00:00+00:00'
[2024-10-04T01:23:25.936+0000] {_metadata.py:139} WARNING - Compute Engine Metadata server unavailable on attempt 1 of 3. Reason: timed out
[2024-10-04T01:23:28.945+0000] {_metadata.py:139} WARNING - Compute Engine Metadata server unavailable on attempt 2 of 3. Reason: timed out
[2024-10-04T01:23:28.950+0000] {_metadata.py:139} WARNING - Compute Engine Metadata server unavailable on attempt 3 of 3. Reason: [Errno 111] Connection refused
[2024-10-04T01:23:28.951+0000] {_default.py:338} WARNING - Authentication failed using Compute Engine authentication due to unavailable metadata server.
[2024-10-04T01:23:28.952+0000] {taskinstance.py:1937} ERROR - Task failed with exception
Traceback (most recent call last):
  File "/home/airflow/.local/lib/python3.8/site-packages/airflow/operators/python.py", line 192, in execute
    return_value = self.execute_callable()
  File "/home/airflow/.local/lib/python3.8/site-packages/airflow/operators/python.py", line 209, in execute_callable
    return self.python_callable(*self.op_args, **self.op_kwargs)
  File "/opt/airflow/dags/data_ingestion_gcs_dag.py", line 47, in upload_to_gcs
    client = storage.Client()
  File "/home/airflow/.local/lib/python3.8/site-packages/google/cloud/storage/client.py", line 172, in __init__
    super(Client, self).__init__(
  File "/home/airflow/.local/lib/python3.8/site-packages/google/cloud/client/__init__.py", line 320, in __init__
    _ClientProjectMixin.__init__(self, project=project, credentials=credentials)
  File "/home/airflow/.local/lib/python3.8/site-packages/google/cloud/client/__init__.py", line 268, in __init__
    project = self._determine_default(project)
  File "/home/airflow/.local/lib/python3.8/site-packages/google/cloud/client/__init__.py", line 287, in _determine_default
    return _determine_default_project(project)
  File "/home/airflow/.local/lib/python3.8/site-packages/google/cloud/_helpers/__init__.py", line 152, in _determine_default_project
    _, project = google.auth.default()
  File "/home/airflow/.local/lib/python3.8/site-packages/google/auth/_default.py", line 691, in default
    raise exceptions.DefaultCredentialsError(_CLOUD_SDK_MISSING_CREDENTIALS)
google.auth.exceptions.DefaultCredentialsError: Your default credentials were not found. To set up Application Default Credentials, see https://cloud.google.com/docs/authentication/external/set-up-adc for more information.
[2024-10-04T01:23:28.967+0000] {taskinstance.py:1400} INFO - Marking task as FAILED. dag_id=data_ingestion_gcs_dag, task_id=local_to_gcs_task, execution_date=20241003T000000, start_date=20241004T012322, end_date=20241004T012328
[2024-10-04T01:23:28.982+0000] {standard_task_runner.py:104} ERROR - Failed to execute job 13 for task local_to_gcs_task (Your default credentials were not found. To set up Application Default Credentials, see https://cloud.google.com/docs/authentication/external/set-up-adc for more information.; 882)
[2024-10-04T01:23:29.011+0000] {local_task_job_runner.py:228} INFO - Task exited with return code 1
[2024-10-04T01:23:29.023+0000] {taskinstance.py:2778} INFO - 0 downstream tasks scheduled from follow-on schedule check
