[2024-10-16T16:53:25.834+0000] {taskinstance.py:1159} INFO - Dependencies all met for dep_context=non-requeueable deps ti=<TaskInstance: zone_data_ingestion_gcs_dag.local_to_gcs_task scheduled__2024-10-15T00:00:00+00:00 [queued]>
[2024-10-16T16:53:25.837+0000] {taskinstance.py:1159} INFO - Dependencies all met for dep_context=requeueable deps ti=<TaskInstance: zone_data_ingestion_gcs_dag.local_to_gcs_task scheduled__2024-10-15T00:00:00+00:00 [queued]>
[2024-10-16T16:53:25.837+0000] {taskinstance.py:1361} INFO - Starting attempt 2 of 3
[2024-10-16T16:53:25.841+0000] {taskinstance.py:1382} INFO - Executing <Task(PythonOperator): local_to_gcs_task> on 2024-10-15 00:00:00+00:00
[2024-10-16T16:53:25.843+0000] {standard_task_runner.py:57} INFO - Started process 148 to run task
[2024-10-16T16:53:25.845+0000] {standard_task_runner.py:84} INFO - Running: ['***', 'tasks', 'run', 'zone_data_ingestion_gcs_dag', 'local_to_gcs_task', 'scheduled__2024-10-15T00:00:00+00:00', '--job-id', '92', '--raw', '--subdir', 'DAGS_FOLDER/zone_data_ingestion_gcs_dag.py', '--cfg-path', '/tmp/tmp1wmpl4s3']
[2024-10-16T16:53:25.845+0000] {standard_task_runner.py:85} INFO - Job 92: Subtask local_to_gcs_task
[2024-10-16T16:53:25.861+0000] {task_command.py:416} INFO - Running <TaskInstance: zone_data_ingestion_gcs_dag.local_to_gcs_task scheduled__2024-10-15T00:00:00+00:00 [running]> on host 047025be9b5c
[2024-10-16T16:53:25.885+0000] {taskinstance.py:1662} INFO - Exporting env vars: AIRFLOW_CTX_DAG_OWNER='***' AIRFLOW_CTX_DAG_ID='zone_data_ingestion_gcs_dag' AIRFLOW_CTX_TASK_ID='local_to_gcs_task' AIRFLOW_CTX_EXECUTION_DATE='2024-10-15T00:00:00+00:00' AIRFLOW_CTX_TRY_NUMBER='2' AIRFLOW_CTX_DAG_RUN_ID='scheduled__2024-10-15T00:00:00+00:00'
[2024-10-16T16:53:25.940+0000] {taskinstance.py:1937} ERROR - Task failed with exception
Traceback (most recent call last):
  File "/home/airflow/.local/lib/python3.8/site-packages/airflow/operators/python.py", line 192, in execute
    return_value = self.execute_callable()
  File "/home/airflow/.local/lib/python3.8/site-packages/airflow/operators/python.py", line 209, in execute_callable
    return self.python_callable(*self.op_args, **self.op_kwargs)
  File "/opt/airflow/dags/zone_data_ingestion_gcs_dag.py", line 56, in upload_to_gcs
    blob.upload_from_filename(local_file)
  File "/home/airflow/.local/lib/python3.8/site-packages/google/cloud/storage/blob.py", line 2926, in upload_from_filename
    self._handle_filename_and_upload(
  File "/home/airflow/.local/lib/python3.8/site-packages/google/cloud/storage/blob.py", line 2794, in _handle_filename_and_upload
    with open(filename, "rb") as file_obj:
FileNotFoundError: [Errno 2] No such file or directory: '/opt/airflow/taxi_zone_lookup.parquet'
[2024-10-16T16:53:25.943+0000] {taskinstance.py:1400} INFO - Marking task as UP_FOR_RETRY. dag_id=zone_data_ingestion_gcs_dag, task_id=local_to_gcs_task, execution_date=20241015T000000, start_date=20241016T165325, end_date=20241016T165325
[2024-10-16T16:53:25.946+0000] {standard_task_runner.py:104} ERROR - Failed to execute job 92 for task local_to_gcs_task ([Errno 2] No such file or directory: '/opt/airflow/taxi_zone_lookup.parquet'; 148)
[2024-10-16T16:53:25.950+0000] {local_task_job_runner.py:228} INFO - Task exited with return code 1
[2024-10-16T16:53:25.959+0000] {taskinstance.py:2778} INFO - 0 downstream tasks scheduled from follow-on schedule check
