[2024-10-10T17:46:48.805+0000] {taskinstance.py:1159} INFO - Dependencies all met for dep_context=non-requeueable deps ti=<TaskInstance: green_data_ingestion_gcs_dag.download_dataset_task manual__2024-10-10T17:45:44.643567+00:00 [queued]>
[2024-10-10T17:46:48.807+0000] {taskinstance.py:1159} INFO - Dependencies all met for dep_context=requeueable deps ti=<TaskInstance: green_data_ingestion_gcs_dag.download_dataset_task manual__2024-10-10T17:45:44.643567+00:00 [queued]>
[2024-10-10T17:46:48.808+0000] {taskinstance.py:1361} INFO - Starting attempt 1 of 2
[2024-10-10T17:46:48.811+0000] {taskinstance.py:1382} INFO - Executing <Task(PythonOperator): download_dataset_task> on 2024-10-10 17:45:44.643567+00:00
[2024-10-10T17:46:48.814+0000] {standard_task_runner.py:57} INFO - Started process 29973 to run task
[2024-10-10T17:46:48.816+0000] {standard_task_runner.py:84} INFO - Running: ['***', 'tasks', 'run', 'green_data_ingestion_gcs_dag', 'download_dataset_task', 'manual__2024-10-10T17:45:44.643567+00:00', '--job-id', '37', '--raw', '--subdir', 'DAGS_FOLDER/green_data_ingestion_gcs_dag.py', '--cfg-path', '/tmp/tmpxznc37lq']
[2024-10-10T17:46:48.816+0000] {standard_task_runner.py:85} INFO - Job 37: Subtask download_dataset_task
[2024-10-10T17:46:48.832+0000] {task_command.py:416} INFO - Running <TaskInstance: green_data_ingestion_gcs_dag.download_dataset_task manual__2024-10-10T17:45:44.643567+00:00 [running]> on host 72e947e9fa68
[2024-10-10T17:46:48.855+0000] {taskinstance.py:1662} INFO - Exporting env vars: AIRFLOW_CTX_DAG_OWNER='***' AIRFLOW_CTX_DAG_ID='green_data_ingestion_gcs_dag' AIRFLOW_CTX_TASK_ID='download_dataset_task' AIRFLOW_CTX_EXECUTION_DATE='2024-10-10T17:45:44.643567+00:00' AIRFLOW_CTX_TRY_NUMBER='1' AIRFLOW_CTX_DAG_RUN_ID='manual__2024-10-10T17:45:44.643567+00:00'
[2024-10-10T17:46:53.022+0000] {taskinstance.py:1937} ERROR - Task failed with exception
Traceback (most recent call last):
  File "/home/airflow/.local/lib/python3.8/site-packages/airflow/operators/python.py", line 192, in execute
    return_value = self.execute_callable()
  File "/home/airflow/.local/lib/python3.8/site-packages/airflow/operators/python.py", line 209, in execute_callable
    return self.python_callable(*self.op_args, **self.op_kwargs)
  File "/opt/airflow/dags/green_data_ingestion_gcs_dag.py", line 46, in download_data_and_concat
    final_table = pa.Table.from_pands(final_pf)
AttributeError: type object 'pyarrow.lib.Table' has no attribute 'from_pands'
[2024-10-10T17:46:53.027+0000] {taskinstance.py:1400} INFO - Marking task as UP_FOR_RETRY. dag_id=green_data_ingestion_gcs_dag, task_id=download_dataset_task, execution_date=20241010T174544, start_date=20241010T174648, end_date=20241010T174653
[2024-10-10T17:46:53.031+0000] {standard_task_runner.py:104} ERROR - Failed to execute job 37 for task download_dataset_task (type object 'pyarrow.lib.Table' has no attribute 'from_pands'; 29973)
[2024-10-10T17:46:53.060+0000] {local_task_job_runner.py:228} INFO - Task exited with return code 1
[2024-10-10T17:46:53.071+0000] {taskinstance.py:2778} INFO - 0 downstream tasks scheduled from follow-on schedule check
